

= 08.09.2022 16:04:25 (UTC +8:00) === ECU-TEST 2021.2.113427+6b6fb661af22 113427+6b6fb661af22 (2021/06/28 11:25:11) (64bit) ===

License: ECU-TEST
         - License options:
             + Diagnostics add-on
             + Trace Analysis
         - valid up to version: 2022.4
         - valid until: 31-dec-2022
         - licensed for: TURING
         - Server: 192.168.1.17


2022-09-08 16:04:25.112 15856 ManagedWorker-4*PE.Run() ERROR:
                        Traceback (most recent call last):
                          File "tts\testExecution\engine\TestEngine.py", line 953, in ExecuteTestStep
                          File "tts\testExecution\testSteps\dataoperations\inboxfetch\TsInboxFetchExec.py", line 103, in Run
                          File "tts\testExecution\testSteps\dataoperations\inboxfetch\TsInboxFetchExec.py", line 80, in Call
                          File "tts\core\package\dataStructures\Inbox.py", line 216, in FetchNext
                        tt._Exceptions_.TTError: Waiting for next message not allowed for disconnected inbox
2022-09-08 16:04:25.121 15856 ManagedWorker-4*PE.Run() ERROR:
                        Traceback (most recent call last):
                          File "tts\testExecution\engine\TestEngine.py", line 953, in ExecuteTestStep
                          File "tts\testExecution\testSteps\dataoperations\inboxfetch\TsInboxFetchExec.py", line 103, in Run
                          File "tts\testExecution\testSteps\dataoperations\inboxfetch\TsInboxFetchExec.py", line 80, in Call
                          File "tts\core\package\dataStructures\Inbox.py", line 216, in FetchNext
                        tt._Exceptions_.TTError: Waiting for next message not allowed for disconnected inbox
2022-09-08 16:04:25.134 15856 ManagedWorker-4*PE.Run() ERROR:
                        Traceback (most recent call last):
                          File "tts\testExecution\engine\TestEngine.py", line 953, in ExecuteTestStep
                          File "tts\testExecution\testSteps\dataoperations\inboxfetch\TsInboxFetchExec.py", line 103, in Run
                          File "tts\testExecution\testSteps\dataoperations\inboxfetch\TsInboxFetchExec.py", line 80, in Call
                          File "tts\core\package\dataStructures\Inbox.py", line 216, in FetchNext
                        tt._Exceptions_.TTError: Waiting for next message not allowed for disconnected inbox
2022-09-08 16:04:25.143 15856 ManagedWorker-4*PE.Run() ERROR:
                        Traceback (most recent call last):
                          File "tts\testExecution\engine\TestEngine.py", line 953, in ExecuteTestStep
                          File "tts\testExecution\testSteps\dataoperations\inboxfetch\TsInboxFetchExec.py", line 103, in Run
                          File "tts\testExecution\testSteps\dataoperations\inboxfetch\TsInboxFetchExec.py", line 80, in Call
                          File "tts\core\package\dataStructures\Inbox.py", line 216, in FetchNext
                        tt._Exceptions_.TTError: Waiting for next message not allowed for disconnected inbox
2022-09-08 16:04:25.155 15856 ManagedWorker-4*PE.Run() ERROR:
                        Traceback (most recent call last):
                          File "tts\testExecution\engine\TestEngine.py", line 953, in ExecuteTestStep
                          File "tts\testExecution\testSteps\dataoperations\inboxfetch\TsInboxFetchExec.py", line 103, in Run
                          File "tts\testExecution\testSteps\dataoperations\inboxfetch\TsInboxFetchExec.py", line 80, in Call
                          File "tts\core\package\dataStructures\Inbox.py", line 216, in FetchNext
                        tt._Exceptions_.TTError: Waiting for next message not allowed for disconnected inbox
2022-09-08 16:04:25.165 15856 ManagedWorker-4*PE.Run() ERROR:
                        Traceback (most recent call last):
                          File "tts\testExecution\engine\TestEngine.py", line 953, in ExecuteTestStep
                          File "tts\testExecution\testSteps\dataoperations\inboxfetch\TsInboxFetchExec.py", line 103, in Run
                          File "tts\testExecution\testSteps\dataoperations\inboxfetch\TsInboxFetchExec.py", line 80, in Call
                          File "tts\core\package\dataStructures\Inbox.py", line 216, in FetchNext
                        tt._Exceptions_.TTError: Waiting for next message not allowed for disconnected inbox
2022-09-08 16:04:25.174 15856 ManagedWorker-4*PE.Run() ERROR:
                        Traceback (most recent call last):
                          File "tts\testExecution\engine\TestEngine.py", line 953, in ExecuteTestStep
                          File "tts\testExecution\testSteps\dataoperations\inboxfetch\TsInboxFetchExec.py", line 103, in Run
                          File "tts\testExecution\testSteps\dataoperations\inboxfetch\TsInboxFetchExec.py", line 80, in Call
                          File "tts\core\package\dataStructures\Inbox.py", line 216, in FetchNext
                        tt._Exceptions_.TTError: Waiting for next message not allowed for disconnected inbox
2022-09-08 16:04:25.185 15856 ManagedWorker-4*PE.Run() ERROR:
                        Traceback (most recent call last):
                          File "tts\testExecution\engine\TestEngine.py", line 953, in ExecuteTestStep
                          File "tts\testExecution\testSteps\dataoperations\inboxfetch\TsInboxFetchExec.py", line 103, in Run
                          File "tts\testExecution\testSteps\dataoperations\inboxfetch\TsInboxFetchExec.py", line 80, in Call
                          File "tts\core\package\dataStructures\Inbox.py", line 216, in FetchNext
                        tt._Exceptions_.TTError: Waiting for next message not allowed for disconnected inbox
2022-09-08 16:04:25.195 15856 ManagedWorker-4*PE.Run() ERROR:
                        Traceback (most recent call last):
                          File "tts\testExecution\engine\TestEngine.py", line 953, in ExecuteTestStep
                          File "tts\testExecution\testSteps\dataoperations\inboxfetch\TsInboxFetchExec.py", line 103, in Run
                          File "tts\testExecution\testSteps\dataoperations\inboxfetch\TsInboxFetchExec.py", line 80, in Call
                          File "tts\core\package\dataStructures\Inbox.py", line 216, in FetchNext
                        tt._Exceptions_.TTError: Waiting for next message not allowed for disconnected inbox
